Workbook

Sheet Read me
A1: Prevention Returns Ledger
A2: Oxon Advisory Prevention Informatics. Sources checked 27 September 2026.
A4: What this workbook holds
A5: Ledger | B5: Every harm cost, intervention, valuation parameter and forecast, one row each, with source, URL, price year and evidence grade. Filter with the header arrows.
A6: Parameters | B6: Official valuation values (QALY, WELLBY, NICE threshold, discount rates) and the ACE burden base. Blue cells are inputs you can change.
A7: Scenarios | B7: Applies each source's published ratio to a caseload or spend you enter in the yellow cells. Results are illustrative arithmetic on sourced parameters, not new estimates.
A9: Evidence grades
A10: A | B10: Official statistics, UK randomised trial or systematic review
A11: B | B11: Peer-reviewed cohort, quasi-experimental study or official evaluation
A12: C | B12: Modelled estimate (peer-reviewed, think tank or charity), or an international effect with no UK cost
A13: D | B13: Secondary citation; primary source not seen
A15: Colour conventions
A16: Blue text | B16: Hard-coded input taken from a source (change only if you have a better source)
A17: Yellow fill | B17: Your scenario input
A18: Black text | B18: Formula
A19: Green text | B19: Link to another sheet
A21: Handling rules
B22: Figures are not rebased to a common price year. Rebase before comparing across rows.
B23: Harm costs overlap heavily and must never be summed.
B24: Cash returns and QALY values come from different frameworks; combining them needs a stated assumption.
B25: Human security tags (want, fear, dignity) are Oxon Advisory's classification, not the sources'.
A27: Known gaps
B28: No verified cost estimate for children with a parent in prison (219,000 a year).
B29: No cost-effectiveness study for brain injury screening or linkworker support in justice settings.
B30: No UK cost-of-illness estimate for FASD, and no verified UK return for children's speech and language therapy.
B31: EIF's late intervention estimate has not been updated since 2016.
B32: Most youth violence effect sizes come from outside the UK; UK trials of MST, FFT and FNP were null or not cost-effective.
B33: Scotland, Wales and Northern Ireland are thin outside alcohol pricing and the CPIT trials.
B34: Few sources report QALYs; most report cash returns, so health and cash values cannot be combined without assumptions.

Sheet Ledger
A1: ID | B1: Entry type | C1: Life stage | D1: Age band | E1: Neurodevelopmental window | F1: System | G1: Human security | H1: Item | I1: Measure | J1: Value | K1: Result | L1: Pays | M1: Benefits | N1: Grade | O1: Design | P1: Where | Q1: Price year | R1: Source | S1: URL | T1: Note
A2: H01 | B2: Harm cost | C2: Whole lifecourse | D2: and next generation | F2: Cross-system | G2: Freedom from want | H2: Late intervention spend (children and young people) | I2: State spend per year | J2: £16.6bn (nearly £17bn); £287 per person. LA £6.4bn, NHS £3.7bn, DWP £2.7bn | N2: B | O2: Analysis of public spend | P2: England and Wales | Q2: 2016/17 | R2: EIF, The cost of late intervention: EIF analysis 2016 | S2: https://foundations.org.uk/our-work/publications/the-cost-of-late-intervention-eif-analysis-2016/ | T2: Fiscal only. Excludes long-term cumulative and wider social costs. Not updated since 2016.
A3: H02 | B3: Harm cost | C3: Whole lifecourse | D3: and next generation | F3: Social care | G3: Freedom from want | H3: Children's services spend skewed to crisis | I3: Share of spend on late intervention | J3: £14.7bn in 2024/25, 82% on late intervention; early intervention >40% below 15 years ago | N3: B | O3: Analysis of LA outturn | P3: England | Q3: 2024/25 | R3: Horton and Franklin (2026), Rebalancing the system, Pro Bono Economics | S3: https://learning.nspcc.org.uk/research-resources/childrens-services-spending-reports | T3: Children in care up 25% since 2011; average cost per child in care over £100,000 a year.
A4: H03 | B4: Harm cost | C4: Pregnancy | D4: −9 to 0 months | E4: Prenatal exposures | F4: Health | G4: Freedom to live in dignity | H4: Perinatal depression, anxiety and psychosis | I4: Long-term cost per annual birth cohort | J4: £8.1bn (≈£10,000 per birth); 72% relates to the child; £1.7bn public sector; £337m a year to meet guidance | N4: C | O4: Cost model | P4: UK | Q4: 2014 report | R4: Bauer et al. (2014), LSE and Centre for Mental Health | S4: https://www.centreformentalhealth.org.uk/wp-content/uploads/2018/09/costsofperinatalsummary.pdf | T4: The clearest measured intergenerational cost in the UK literature. Critics note most of the total is not cash spend.
A5: H04 | B5: Harm cost | C5: Pregnancy | D5: −9 to 0 months | E5: Prenatal exposures | F5: Health | G5: Freedom to live in dignity | H5: Smoking in pregnancy | I5: Excess child health-care cost | J5: £91 per child at age 1; £222 by age 5; not significant by age 10 | N5: B | O5: Linked cohort (93,152 pregnancies) | P5: England | Q5: 2015 | R5: Vaz et al. (2018), Addiction | S5: https://doi.org/10.1111/add.14183 | T5: Driven mainly by inpatient care. No total annual NHS cost verified.
A6: H05 | B6: Harm cost | C6: Pregnancy | D6: −9 to 0 months | E6: Neurodevelopmental conditions | F6: Health | G6: Freedom to live in dignity | H6: Fetal alcohol spectrum disorder (FASD) | I6: Prevalence | J6: 1.8% (95% CI 1.0–3.4); 3.6% including possible cases. Screening estimates in ALSPAC 6–17% | N6: B | O6: Active case ascertainment (n=220) | P6: Greater Manchester | Q6: n/a | R6: McCarthy et al. (2021), ACER; McQuire et al. (2019), Prev Med | S6: https://doi.org/10.1111/acer.14705 | T6: No case had been identified before. No UK cost-of-illness estimate verified. NICE QS204 (2022) sets standards.
A7: H06 | B7: Harm cost | C7: Pregnancy | D7: −9 to 0 months | E7: Attachment, language and self-regulation | F7: Health | G7: Freedom to live in dignity | H7: Preterm birth | I7: Public-sector cost to age 18 per birth cohort | J7: £2.946bn; £22,885 per preterm child; £94,740 extremely preterm | N7: C | O7: Decision model | P7: England and Wales | Q7: 2006 | R7: Mangham et al. (2009), Pediatrics | S7: http://wrap.warwick.ac.uk/37026/ | T7: 92% of incremental cost is neonatal inpatient care. No UK update verified.
A8: H07 | B8: Harm cost | C8: Early years | D8: 0–5 | E8: Attachment, language and self-regulation | F8: Social care | G8: Freedom from fear | H8: Child maltreatment and parental domestic abuse | I8: Lifetime societal cost | J8: £71,309 per child exposed; £27.8bn for the 2013 UK birth cohort | N8: C | O8: Lifetime cost model | P8: UK | Q8: 2019 | R8: Herbert et al. (2025), Child Abuse & Neglect 163, 107435 | S8: https://pubmed.ncbi.nlm.nih.gov/40168916/ | T8: Includes cost of exposed children later perpetrating intimate partner violence. Co-occurring abuse costs more than either alone.
A9: H08 | B9: Harm cost | C9: Whole lifecourse | D9: and next generation | F9: Cross-system | G9: Freedom from fear | H9: Adverse childhood experiences (ACEs) | I9: Annual cost and DALYs attributable | J9: US$78.6bn a year (2.8% of GDP); 1,858,700 DALYs | N9: C | O9: Meta-analysis and burden model | P9: UK | Q9: 2019 US$ | R9: Hughes et al. (2021), Lancet Public Health | S9: https://doi.org/10.1016/S2468-2667(21)00232-2 | T9: DALYs valued at GDP per capita (US$42,300 for the UK). Authors caution against cross-country comparison.
A10: H09 | B10: Harm cost | C10: Early years | D10: 0–5 | E10: Neurodevelopmental conditions | F10: Education | G10: Freedom to live in dignity | H10: Developmental language disorder (DLD) | I10: Prevalence at school entry | J10: 7.58% (≈2 children per class of 30); 88% did not make expected academic progress | N10: B | O10: Population survey (n=7,267 screened) | P10: Surrey | Q10: n/a | R10: Norbury et al. (2016), JCPP | S10: https://doi.org/10.1111/jcpp.12573 | T10: No verified UK return figure for speech and language therapy for children.
A11: H10 | B11: Harm cost | C11: Middle childhood | D11: 5–11 | E11: Executive function, learning and behaviour | F11: Cross-system | G11: Freedom from fear | H11: Childhood conduct disorder | I11: Public service cost to age 28 | J11: 10 times higher than peers: £70,019 against £7,423 per person | N11: B | O11: Cohort follow-up (n=142) | P11: Inner London | Q11: 1998 | R11: Scott et al. (2001), BMJ | S11: https://pubmed.ncbi.nlm.nih.gov/11473907/ | T11: Crime was the largest cost, then extra education, foster and residential care, and benefits.
A12: H11 | B12: Harm cost | C12: Middle childhood | D12: 5–11 | E12: Executive function, learning and behaviour | F12: Economy and welfare | G12: Freedom from fear | H12: Childhood bullying victimisation | I12: Costs at age 50 | J12: Men: £271 a year higher employment-related costs. Women: £717 higher health service costs over 8 years | N12: B | O12: 1958 British birth cohort | P12: Great Britain | Q12: 2008 | R12: Brimblecombe et al. (2018), Social Science & Medicine | S12: https://doi.org/10.1016/j.socscimed.2018.05.014 | T12: Bullied people were less often employed and held less wealth four decades later.
A13: H12 | B13: Harm cost | C13: Adolescence | D13: 11–18 | E13: Executive function, learning and behaviour | F13: Education | G13: Freedom from want | H13: Permanent school exclusion | I13: Lifetime cost to the state | J13: At least £170,000 per child; £1.6bn per annual cohort | N13: C | O13: Think tank model | P13: England | Q13: 2023/24 | R13: IPPR and The Difference (2024) | S13: https://www.ippr.org/media-office/revealed-school-exclusions-and-suspensions-rise-by-a-fifth-last-year-finds-new-report | T13: Supersedes the widely quoted 2017 figure of £370,000.
A14: H13 | B14: Harm cost | C14: Whole lifecourse | D14: and next generation | E14: Neurodevelopmental conditions | F14: Cross-system | G14: Freedom to live in dignity | H14: ADHD | I14: Avoidable economic cost | J14: At least £17bn; about £17,000 more per adult per year | N14: C | O14: Danish registry sibling comparison, scaled to the UK adult population | P14: UK | Q14: not stated | R14: NHS England, Independent ADHD Taskforce Part 1 (2025), converting Daley et al. (2019) | S14: https://www.england.nhs.uk/long-read/report-of-the-independent-adhd-taskforce-part-1/ | T14: Daley et al. (2019) report in euros, from 2010 Danish register data: €20,135 more per adult with ADHD per year than a same-sex sibling (p.45), and €19,974m for the UK at 2.5% prevalence or €4,361m at 0.5% (Table 4, p.46), which the paper calls crude estimates. The Taskforce converted to pounds at an unstated rate and uses the higher prevalence. Taskforce links ADHD to early justice contact; 20–34% of NEET young people likely to have ADHD.
A15: H14 | B15: Harm cost | C15: Whole lifecourse | D15: and next generation | E15: Neurodevelopmental conditions | F15: Cross-system | G15: Freedom to live in dignity | H15: Autism | I15: Lifetime cost per person | J15: £1.5m with intellectual disability; £0.92m without | N15: C | O15: Literature-based model | P15: UK | Q15: ≈2011 | R15: Buescher et al. (2014), JAMA Pediatrics | S15: https://doi.org/10.1001/jamapediatrics.2014.210 | T15: In childhood the main costs are special education and lost parental productivity.
A16: H15 | B16: Harm cost | C16: Adolescence | D16: 11–18 | E16: Acquired brain injury | F16: Justice | G16: Freedom to live in dignity | H16: Traumatic brain injury in adolescence | I16: Lifetime cost per case at age 15 | J16: £155,000 in the general population; £345,000 for a young person in a YOI | N16: C | O16: Cost model | P16: UK | Q16: ≈2016 | R16: Centre for Mental Health (2016), Traumatic brain injury and offending | S16: https://www.centreformentalhealth.org.uk/publications/traumatic-brain-injury-and-offending/ | T16: Crime costs drive the difference (£60,000 against £250,000).
A17: H16 | B17: Harm cost | C17: Adolescence | D17: 11–18 | E17: Acquired brain injury | F17: Justice | G17: Freedom to live in dignity | H17: Brain injury among children in custody | I17: Prevalence | J17: 82% reported at least one TBI; 44% with ongoing symptoms | N17: B | O17: Cohort (93 males aged 15–18) | P17: England | Q17: n/a | R17: Chitsabesan et al. (2015), J Head Trauma Rehabil | S17: https://doi.org/10.1097/HTR.0000000000000129 | T17: International review range 16.5–72.1% (Hughes et al. 2015).
A18: H17 | B18: Harm cost | C18: Adulthood | D18: 25+ | E18: Acquired brain injury | F18: Justice | G18: Freedom to live in dignity | H18: Brain injury among adults in prison | I18: Prevalence | J18: 65% of adult male prisoners report TBI (16% moderate to severe); 78% of women in Scottish prisons had significant head injury | N18: B | O18: Surveys | P18: England; Scotland | Q18: n/a | R18: Williams et al. (2010), Brain Injury; McMillan et al. (2021), Lancet Psychiatry | S18: https://doi.org/10.3109/02699052.2010.495697 | T18: Among women, injuries mostly linked to domestic abuse, often repeated.
A19: H18 | B19: Harm cost | C19: Whole lifecourse | D19: and next generation | E19: Acquired brain injury | F19: Health | G19: Freedom to live in dignity | H19: Acquired brain injury (traumatic brain injury, stroke and brain tumour) | I19: Annual cost to the economy | J19: £43bn: NHS and social care £20bn; productivity £21.5bn; justice and education £1.5bn; plus benefits £1.9bn, outside the total (transfers) | N19: C | O19: Charity-commissioned model | P19: UK | Q19: 2023/24 | R19: APPG on ABI and UKABIF (2025), The cost of acquired brain injury to the UK economy | S19: https://ukabif.org.uk/news/701354/Hidden-toll-of-brain-injury-costs-economy-43-billion-a-year-.htm | T19: Covers traumatic brain injury, stroke and brain tumour, about 85% of ABI episodes; other causes are not costed (p.9). The report calls the total both the lifetime costs of ABI in 2023/24 (p.9) and a typical year (p.25). Price bases are mixed. Wellbeing loss of £91.5bn a year reported separately (pp.5, 7).
A20: H19 | B20: Harm cost | C20: Adolescence | D20: 11–18 | F20: Social care | G20: Freedom from want | H20: Residential care for children | I20: Spend per child per year | J20: Children's home £318,400 (£6,100 a week); foster care £38,100. £8.1bn LA spend for 83,630 looked-after children | N20: A | O20: NAO audit | P20: England | Q20: 2023/24 | R20: NAO (2025), Managing children's residential care | S20: https://www.nao.org.uk/wp-content/uploads/2025/09/Managing-childrens-residential-care.pdf | T20: CMA (2022) found the largest providers earn materially higher profits than a working market would. NAO figure is spend per child; its residential category includes secure units, residential care homes and residential schools.
A21: H20 | B21: Harm cost | C21: Young adulthood | D21: 18–25 | E21: Adolescent social and emotional development | F21: Economy and welfare | G21: Freedom from want | H21: Young people not in education, employment or training (NEET) | I21: Lifetime and annual cost | J21: £244,000 per additional NEET young person (lifetime, state). Almost 1m NEET: £125bn cumulative annual cost | N21: C | O21: Think tank and review models | P21: England/UK | Q21: 2026 | R21: Impetus (2026), Closing the Youth Jobs Gap; DWP, Young people and work: interim report (2026) | S21: https://www.gov.uk/government/publications/young-people-and-work-interim-report/young-people-and-work-interim-report | T21: Review found only about one in five NEET young people get meaningful employment support.
A22: H21 | B22: Harm cost | C22: Adulthood | D22: 25+ | E22: Adult mental health, recovery and parenting | F22: Health | G22: Freedom to live in dignity | H22: Mental ill health | I22: Economic and social cost | J22: £300bn in 2022; £25bn falls on the state, £101bn on business, £175bn on people and families | N22: C | O22: Cost-of-illness model | P22: England | Q22: 2022 | R22: Cardoso and McHayle (2024), Centre for Mental Health | S22: https://www.centreformentalhealth.org.uk/publications/the-economic-and-social-costs-of-mental-ill-health/ | T22: Excludes £2.1bn cost of mental ill health in prisons.
A23: H22 | B23: Harm cost | C23: Adulthood | D23: 25+ | E23: Adult mental health, recovery and parenting | F23: Health | G23: Freedom from fear | H23: Alcohol harm | I23: External cost per year | J23: £27.44bn: NHS £4.91bn; crime and justice £14.58bn; productivity £5.06bn; social services £2.89bn | N23: C | O23: Cabinet Office method, updated | P23: England | Q23: not stated | R23: Institute of Alcohol Studies (2024) | S23: https://www.ias.org.uk/factsheet/economy/ | T23: Data year 2021/22; price base not stated for all components (methodology, pp.1–2). Contested: critics argue little falls directly on taxpayers and that this is a cost, not cost-benefit, analysis.
A24: H23 | B24: Harm cost | C24: Adulthood | D24: 25+ | E24: Adult mental health, recovery and parenting | F24: Justice | G24: Freedom from fear | H24: Illicit drug use | I24: Cost to society per year | J24: Over £19bn: crime and justice £9.3bn; deaths £6.3bn; children's social care £0.6bn; treatment and prevention £0.6bn | N24: B | O24: Independent government review | P24: England | Q24: not stated | R24: Black (2021), Review of drugs part two, annexes | S24: https://assets.publishing.service.gov.uk/media/60eef5588fa8f50c768386fd/independent-review-of-drugs-part-2-annexes.pdf | T24: Cost year 2017/18; unpublished Public Health England analysis for England (Black 2020, Part One evidence pack, p.14). Spend on treatment is a small fraction of the harm it addresses.
A25: H24 | B25: Harm cost | C25: Adulthood | D25: 25+ | F25: Health | G25: Freedom to live in dignity | H25: Smoking | I25: Cost to the public finances | J25: £16.9bn a year; net £9.1bn after £7.5bn tobacco tax and reduced pensions | N25: C | O25: Charity-commissioned model | P25: England | Q25: 2026 | R25: ASH, Economic impact of smoking | S25: https://ash.org.uk/key-topics/the-economic-impact-of-smoking | T25: Estimates have risen with each revision; method challenged by free-market critics.
A26: H25 | B26: Harm cost | C26: Adulthood | D26: 25+ | F26: Health | G26: Freedom to live in dignity | H26: Obesity and overweight | I26: Annual cost | J26: £98bn, of which about £35bn falls on the state and wider society (NHS £19bn, productivity £16bn) | N26: C | O26: Consultancy model | P26: UK | Q26: 2023 | R26: Frontier Economics (2023), The rising cost of obesity in the UK | S26: https://www.frontier-economics.com/uk/en/news-and-insights/news/news-article-i20358-the-rising-cost-of-obesity-in-the-uk/ | T26: A 2025 Frontier/Nesta revision reports £126bn including overweight; figures move with method.
A27: H26 | B27: Harm cost | C27: Whole lifecourse | D27: and next generation | F27: Economy and welfare | G27: Freedom from want | H27: Child poverty | I27: Annual cost | J27: £39.5bn: services £17.4bn; lost earnings £12.3bn; lost tax £5.0bn; benefits £1.6bn | N27: C | O27: Cost model | P27: UK | Q27: 2023 | R27: Hirsch (2023), The cost of child poverty in 2023, CPAG | S27: https://cpag.org.uk/news/official-child-poverty-statistics-350000-more-children-poverty-and-numbers-will-rise | T27: Most service cost falls on schools (£4.5bn), children's social services (£4.2bn) and health (£3.5bn).
A28: H27 | B28: Harm cost | C28: Whole lifecourse | D28: and next generation | F28: Housing | G28: Freedom from want | H28: Temporary accommodation for homeless households | I28: Council spend per year | J28: £2.84bn gross; £1.43bn net. More than doubled in five years | N28: A | O28: Official outturn | P28: England | Q28: 2024/25 | R28: House of Commons Library, CBP-10421 (2026) | S28: https://commonslibrary.parliament.uk/research-briefings/cbp-10421/ | T28: Councils' share of TA cost rose from 7.1% (2009/10) to 50.6% (2024/25).
A29: H28 | B29: Harm cost | C29: Adulthood | D29: 25+ | F29: Justice | G29: Freedom from fear | H29: Domestic abuse | I29: Economic and social cost | J29: £66bn; £34,015 per victim | N29: B | O29: Home Office cost-of-crime method | P29: England and Wales | Q29: 2016/17 | R29: Home Office (2019); OSR correspondence on method | S29: https://osr.statisticsauthority.gov.uk/correspondence/reporting-the-costs-of-domestic-abuse | T29: Quality-of-life and output costs cover three years, so not a simple annual figure. Excludes child victims.
A30: H29 | B30: Harm cost | C30: Adulthood | D30: 25+ | F30: Justice | G30: Freedom from fear | H30: Crime | I30: Economic and social cost | J30: £61bn against individuals; £17bn against businesses | N30: B | O30: Home Office cost-of-crime method | P30: England and Wales | Q30: 2019/20 | R30: Home Office, Economic and social costs of crime 2019 to 2020 | S30: https://www.gov.uk/government/publications/economic-and-social-costs-of-crime-2019-to-2020/economic-and-social-costs-of-crime-2019-to-2020 | T30: Violent crime makes up most of the cost to individuals.
A31: H30 | B31: Harm cost | C31: Adulthood | D31: 25+ | F31: Justice | G31: Freedom from fear | H31: Reoffending | I31: Cost per year | J31: £15.0–18.3bn by adults; £1.3–1.6bn by children and young people | N31: B | O31: MoJ analytical report | P31: England and Wales | Q31: 2016/17 | R31: MoJ (2019), Economic and social costs of reoffending | S31: https://assets.publishing.service.gov.uk/media/5d1de7a4e5274a08d13a684e/economic-social-costs-reoffending.pdf
A32: H31 | B32: Harm cost | C32: Adulthood | D32: 25+ | F32: Justice | G32: Freedom from fear | H32: Prison place | I32: Cost per place per year | J32: £59,026 overall resource; £39,454 direct | N32: A | O32: Official statistics | P32: England and Wales | Q32: 2024/25 | R32: MoJ, Costs per place and costs per prisoner 2024 to 2025 | S32: https://assets.publishing.service.gov.uk/media/69bbeea2f7b1c24d8e23ce44/costs-per-place-costs-per-prisoner-2024-2025-summary.pdf | T32: Secure children's homes about £271k and YOIs about £119k per child per year (CMO report, 2025).
A33: H32 | B33: Harm cost | C33: Whole lifecourse | D33: and next generation | F33: Justice | G33: Freedom from fear | H33: Children with a parent in prison | I33: Number per year | J33: 219,000 children (≈2% of school-age children) | N33: A | O33: Linked HMPPS and HMRC data | P33: England and Wales | Q33: Oct 2023–Oct 2024 | R33: MoJ (2026), Updated estimates of children with a parent in prison | S33: https://www.gov.uk/government/publications/updated-estimates-of-children-with-a-parent-in-prison/transparency-data-updated-estimates-of-children-with-a-parent-in-prison | T33: No verified cost estimate exists for this group. A clear evidence gap.
A34: H33 | B34: Harm cost | C34: Whole lifecourse | D34: and next generation | E34: Adult mental health, recovery and parenting | F34: Social care | G34: Freedom to live in dignity | H34: Recurrent care proceedings | I34: Probability of return to court | J34: 27.1% of mothers within 10 years; 41.8% of those returning with a new baby were 14–19 at first birth | N34: B | O34: Population Cafcass data | P34: England | Q34: 2011/12–2020/21 | R34: Nuffield Family Justice Observatory (2023) | S34: https://www.nuffieldfjo.org.uk/resource/mothers-in-recurrent-care-proceedings-new-evidence-for-england-and-wales | T34: Growth reflects more proceedings overall, not higher risk of recurrence.
A35: H34 | B35: Harm cost | C35: Whole lifecourse | D35: and next generation | E35: Adult mental health, recovery and parenting | F35: Social care | G35: Freedom to live in dignity | H35: Children of care-experienced parents | I35: Outcomes against peers | J35: Self-harm 36% against 25%; depression 18% against 11%; mothers in poverty 47% against 24% | N35: B | O35: 1970 BCS and Millennium Cohort Study | P35: Great Britain | Q35: n/a | R35: Parsons et al. (2023); UCL CLS policy briefing (2024) | S35: https://cls.ucl.ac.uk/wp-content/uploads/2017/02/Children-of-care-leavers-policy-briefing.pdf | T35: Children of resilient care-experienced mothers matched peers at GCSE (53% against 29% for other care leavers' children).
A36: H35 | B36: Harm cost | C36: Adulthood | D36: 25+ | E36: Adult mental health, recovery and parenting | F36: Economy and welfare | G36: Freedom from want | H36: Economic inactivity due to sickness | I36: Loss to the Exchequer | J36: At least £11.2bn a year | N36: C | O36: Commission analysis using OBR estimates | P36: UK | Q36: 2023/24 | R36: IPPR Commission on Health and Prosperity (2024), Our greatest asset | S36: https://ippr-org.files.svdcdn.com/production/Downloads/Our_greatest_asset_Sept24.pdf | T36: Tax revenue only: £4.5bn from the 900,000 rise in sickness inactivity since 2020 (IPPR, using the OBR's £5,000 per person), plus the OBR's £3.0bn for in-work ill-health and £3.7bn for indirect effects on other taxes (p.28, note 9). Excludes the rise in benefit spending, which the OBR put at £6.8bn in 2023-24.
A37: H36 | B37: Harm cost | C37: Adolescence | D37: 11–18 | E37: Adolescent social and emotional development | F37: Community safety | G37: Freedom from fear | H37: Serious youth violence | I37: Economic and social cost | J37: About £1.3bn in 2018/19 (minimum £700m), up over 50% since 2014/15 | N37: C | O37: Academic estimate | P37: England and Wales | Q37: 2015/16 | R37: Youth Violence Commission (2020), Final report | S37: https://wrap.warwick.ac.uk/id/eprint/154072/ | T37: In 2015/16 prices, using Home Office unit costs. £1.3bn adds violence not recorded by the police, estimated from the crime survey; £700m uses police-recorded crime only (pp.42, 52). Serious violence affecting children fell in 2024/25 on YEF's three core measures.
A38: I01 | B38: Intervention | C38: Pregnancy | D38: −9 to 0 months | E38: Prenatal exposures | F38: Health | G38: Freedom to live in dignity | H38: Health visitor psychological support to prevent postnatal depression (PoNDER) | I38: Cost per QALY | J38: Dominant: £82 lower cost and +0.002 QALY at 6 months; 99% probability cost-effective at £20k | K38: Cost-saving | L38: NHS community health | M38: NHS; mother and infant | N38: A | O38: Cluster RCT with economic evaluation | P38: England (Trent) | Q38: not stated | R38: Henderson et al. (2019), Psychological Medicine | S38: https://doi.org/10.1017/S0033291718001940 | T38: Lower-risk postnatal women.
A39: I02 | B39: Intervention | C39: Pregnancy | D39: −9 to 0 months | E39: Prenatal exposures | F39: Health | G39: Freedom to live in dignity | H39: Culturally adapted group therapy for postnatal depression (ROSHNI-2) | I39: Cost per QALY | J39: £19,601 per QALY; +£712 cost, +0.036 QALY; 53% probability cost-effective at £20k, 77% at £30k | K39: Cost-effective | L39: NHS | M39: Mother, infant, NHS | N39: A | O39: RCT economic evaluation, 12 months | P39: UK (British South Asian women) | Q39: 2018/19 | R39: Ullah et al. (2025), Lancet Psychiatry (ROSHNI-2 economic evaluation) | S39: https://doi.org/10.1016/S2215-0366(25)00039-2 | T39: Within the 2026 NICE range of £25,000–£35,000.
A40: I03 | B40: Intervention | C40: Pregnancy | D40: −9 to 0 months | E40: Prenatal exposures | F40: Health | G40: Freedom to live in dignity | H40: Financial incentives to stop smoking in pregnancy (CPIT II) | I40: Cost per quitter; lifetime cost per QALY | J40: £1,127 per quitter; £482 per QALY (lifetime) | K40: Cost-effective | L40: NHS maternity | M40: Mother, infant, NHS | N40: A | O40: Phase II RCT plus Markov model | P40: Scotland (Glasgow) | Q40: not stated | R40: Boyd et al. (2016), Addiction | S40: https://doi.org/10.1111/add.13160 | T40: Up to £400 in vouchers. Relapse after birth uncertain.
...

Sheet Parameters
A1: Valuation parameters
A3: Parameter | B3: Value | C3: Unit | D3: Source
A4: Value of a QALY (HM Treasury Green Book) | B4: 70000 | C4: £ (2020/21 prices) | D4: HM Treasury Green Book 2022, Annex 1, A1.63
A5: Value of a WELLBY (central) | B5: 13000 | C5: £ (2019 prices) | D5: HM Treasury (2021) Wellbeing guidance for appraisal
A6: NICE threshold, lower (from April 2026) | B6: 25000 | C6: £ per QALY | D6: NICE (2025) Changes to cost-effectiveness thresholds
A7: NICE threshold, upper (from April 2026) | B7: 35000 | C7: £ per QALY | D7: NICE (2025) Changes to cost-effectiveness thresholds
A8: Standard discount rate (years 1–30) | B8: 0.035 | C8: per year | D8: HM Treasury (2026) Discounting guidance
A9: Health discount rate (years 1–30) | B9: 0.015 | C9: per year | D9: HM Treasury (2026) Discounting guidance
A10: UK DALYs attributable to ACEs | B10: 1858700 | C10: DALYs per year | D10: Hughes et al. (2021) Lancet Public Health
A11: UK GDP per capita used to value DALYs | B11: 42300 | C11: US$ (2019) | D11: Hughes et al. (2021) Lancet Public Health

Sheet Scenarios
A1: Scenario calculator
A2: Enter a caseload (unit-cost rows) or a spend in £ (ratio rows) in the yellow column. Returns apply the source's published ratio; horizon, perspective and price year differ by row.
A4: ID | B4: Intervention | C4: Basis | D4: Unit cost (£) | E4: Ratio low (£ per £1) | F4: Ratio high (£ per £1) | G4: Horizon | H4: Perspective | I4: Price year | J4: Your input (caseload or £) | K4: Cost (£) | L4: Return low (£) | M4: Return high (£) | N4: Net low (£) | O4: Net high (£)
A5: I07 | B5: Parenting programmes | C5: Per unit | D5: 1177 | E5: 2.8 | F5: 6.1 | G5: 25 years | H5: Public sector | I5: 2008/09 | J5: 100 | K5: =IF(C5="Per unit",D5*J5,J5) -> 117700 | L5: =K5*E5 -> 329560 | M5: =K5*F5 -> 717970 | N5: =L5-K5 -> 211860 | O5: =M5-K5 -> 600270
A6: I08 | B6: Sure Start | C6: Per £ spent | E6: 2.05 | F6: 2.05 | G6: Childhood to adulthood | H6: Total (Exchequer ≈0.89) | I6: 2023/24 | J6: 1000000 | K6: =IF(C6="Per unit",D6*J6,J6) -> 1000000 | L6: =K6*E6 -> 2050000 | M6: =K6*F6 -> 2050000 | N6: =L6-K6 -> 1050000 | O6: =M6-K6 -> 1050000
A7: I10 | B7: Social and emotional learning | C7: Per £ spent | E7: 5.05 | F7: 5.05 | G7: 7 years | H7: Societal | I7: 2015 | J7: 1000000 | K7: =IF(C7="Per unit",D7*J7,J7) -> 1000000 | L7: =K7*E7 -> 5050000 | M7: =K7*F7 -> 5050000 | N7: =L7-K7 -> 4050000 | O7: =M7-K7 -> 4050000
A8: I11 | B8: KiVa anti-bullying | C8: Per £ spent | E8: 1.58 | F8: 5.58 | G8: 4 years (to age 18 with wages) | H8: Societal | I8: 2015 | J8: 1000000 | K8: =IF(C8="Per unit",D8*J8,J8) -> 1000000 | L8: =K8*E8 -> 1580000 | M8: =K8*F8 -> 5580000 | N8: =L8-K8 -> 580000 | O8: =M8-K8 -> 4580000
A9: I23 | B9: Youth work | C9: Per £ spent | E9: 3.2 | F9: 6.4 | G9: 10 years | H9: Societal | I9: 2022 | J9: 1000000 | K9: =IF(C9="Per unit",D9*J9,J9) -> 1000000 | L9: =K9*E9 -> 3200000 | M9: =K9*F9 -> 6400000 | N9: =L9-K9 -> 2200000 | O9: =M9-K9 -> 5400000
A10: I26 | B10: Liaison and Diversion | C10: Per unit | D10: 659 | E10: 1.4158 | F10: 1.4158 | G10: Per referral | H10: Criminal justice | I10: not stated | J10: 100 | K10: =IF(C10="Per unit",D10*J10,J10) -> 65900 | L10: =K10*E10 -> 93301.22 | M10: =K10*F10 -> 93301.22 | N10: =L10-K10 -> 27401.22 | O10: =M10-K10 -> 27401.22
A11: I27 | B11: Drug and alcohol treatment | C11: Per £ spent | E11: 4 | F11: 21 | G11: 1 to 10 years | H11: Public sector and society | I11: 2018 | J11: 1000000 | K11: =IF(C11="Per unit",D11*J11,J11) -> 1000000 | L11: =K11*E11 -> 4000000 | M11: =K11*F11 -> 21000000 | N11: =L11-K11 -> 3000000 | O11: =M11-K11 -> 20000000
A12: I28 | B12: MARAC | C12: Per £ spent | E12: 6 | F12: 6 | G12: 1 year | H12: Public sector | I12: 2010 | J12: 1000000 | K12: =IF(C12="Per unit",D12*J12,J12) -> 1000000 | L12: =K12*E12 -> 6000000 | M12: =K12*F12 -> 6000000 | N12: =L12-K12 -> 5000000 | O12: =M12-K12 -> 5000000
A13: I30 | B13: Housing First | C13: Per unit | D13: 10915 | E13: 1.1 | F13: 2.1 | G13: Per year | H13: Public services and wellbeing | I13: 2022 | J13: 100 | K13: =IF(C13="Per unit",D13*J13,J13) -> 1091500 | L13: =K13*E13 -> 1200650 | M13: =K13*F13 -> 2292150 | N13: =L13-K13 -> 109150 | O13: =M13-K13 -> 1200650
A14: I32 | B14: Pause | C14: Per £ spent | E14: 4.5 | F14: 7.61 | G14: 4 to 18 years | H14: Local authority | I14: not stated | J14: 1000000 | K14: =IF(C14="Per unit",D14*J14,J14) -> 1000000 | L14: =K14*E14 -> 4500000 | M14: =K14*F14 -> 7610000 | N14: =L14-K14 -> 3500000 | O14: =M14-K14 -> 6610000
A15: I34 | B15: Public health (review) | C15: Per £ spent | E15: 4.1 | F15: 27.2 | G15: various | H15: Public sector and economy | I15: various | J15: 1000000 | K15: =IF(C15="Per unit",D15*J15,J15) -> 1000000 | L15: =K15*E15 -> 4100000 | M15: =K15*F15 -> 27200000 | N15: =L15-K15 -> 3100000 | O15: =M15-K15 -> 26200000
A18: Valuing health gains
B19: QALYs gained | J19: 100
B20: Social value at Green Book rate | K20: =J19*Parameters!B4 -> 7000000
B21: Maximum NICE would normally accept (lower) | K21: =J19*Parameters!B6 -> 2500000
B22: Maximum NICE would normally accept (upper) | K22: =J19*Parameters!B7 -> 3500000
A24: ACE scenario (illustrative)
B25: Fall in ACE-attributable DALYs | J25: 0.1
B26: DALYs averted per year | K26: =Parameters!B10*J25 -> 185870
B27: Value at UK GDP per capita (US$) | K27: =K26*Parameters!B11 -> 7862301000
B28: Value at £70,000 per DALY (DALY treated as one QALY) | K28: =K26*Parameters!B4 -> 13010900000
A30: Note: assumes burden falls in proportion to ACE prevalence, as Bellis et al. (2019) did for Europe and North America. DALYs and QALYs are different measures; the £70,000 conversion is a simplifying assumption.
